Workbook

Sheet Effektkalkulator ice
A1: Effektberegning på bestemt oppsett av sektorer pr. modell
A2: Effektkalkulator ICE -V5.0
A3: Siteinformasjon | C3: Bruksanvisning effektkalkulator: For å beregne effekttrekk, legg inn antall sektorer pr. modell i cellene B22-B25. Videre brukes cellene B28 + B29 brukes dersom Ice har CSR og/eller RL på site. Kalkulator beregner effekt ved normaldrift i tillegg til snitteffekt etter nettutfall over 2 timer. Eksempel; Large konfig på 3 sektorer gir "3" i celle B24, mens 1x Small, 1x Medium og 1x Large gir "1" i hhv. B22, B23 og B24. Blå felter er input-data. Det er også mulig å legge inn tilgjengelig kapasitet i likeretter i celle B49 + B50 for å sjekke om et gitt valg av sektorer pr. modell kan tilbys innenfor gjeldende kapasitet. Tabell i rad 54 beskriver behov for 48V vern i likeretter til Ice PDU.
A4: Site-ID ICE | B4: MOR07876
A5: Sitenavn ICE | B5: Nørvevika 78
A6: Stasjonseier | B6: Other
A7: Site-ID - Stasjonseier
A8: Sitenavn - Stasjonseier
A9: INSA signatur - Stasjonseier
A10: Dato | B10: 46013
A11: Saksbehandler | B11: Regimantas Kaikaris
A20: Input-data - Effektberegning | B20: Kalkulator bruker ICE-effekter og beregner totalt ift. valgt sammensetning
A21: =_xlfn.CONCAT("Modellsite ice: ",IF(AND(B24>=1,B25>=1),"LARGE + 450",IF(AND(B23>=1,B25>=1),"MEDIUM + 450",IF(AND(B22>=1,B25>=1),"SMALL + 450",IF(B24>=1,"LARGE",IF(B23>=1,"MEDIUM",IF(B22>=1,"SMALL",))))))," (sitenivå)") -> Modellsite ice: LARGE (sitenivå) | B21: Antall sektorer/ baseband | C21: Effekt normaldrift "busy hour" | D21: ICE normaltdrift snitteffekt | E21: Effekt normaltdrift 80% av maks | F21: ICE Effekt batteridrift (450Mhz+800Mhz aktiv) 100% av maks
A22: Small | B22: 0 | C22: 571 | D22: 301 | E22: =0.8*864 -> 691.2 | F22: 540
A23: Medium | C23: =C22+813 -> 1384 | D23: =D22+330 -> 631 | E23: =E22+0.8*1252 -> 1692.8 | F23: 735
A24: Large | B24: 3 | C24: =C23+750 -> 2134 | D24: =D23+396 -> 1027 | E24: =E23+0.8*864 -> 2384 | F24: 1010
A25: Antall sektorer 450Mhz | D25: 176 | E25: =351*0.8 -> 280.8 | F25: 351
A26: Baseband 1 | B26: =IF(AND(OR(B22>0,B23>0),B24=0),1,0) -> 0 | C26: 227 | D26: 227 | E26: 227 | F26: 227
A27: Baseband 2 (N35) | B27: =IF(B24>0,1,0) -> 1 | C27: 376 | D27: 376 | E27: 376 | F27: 376
A28: Basestasjonsaksess (CSR) | B28: 1 | C28: 100 | D28: 100 | E28: 100 | F28: 100
A29: Komplett radiolinje | B29: 0 | C29: 100 | D29: 100 | E29: 100 | F29: 100
A31: Behov likerettermoduler | B31: =B155 -> 5
A32: Maks effekt normaldrift (80% av maks) | B32: =$B$22*E22+$B$23*E23+$B$24*E24+$B$26*E26+$B$27*E27+$B$25*E25+B28*E28+B29*E29 -> 7628 | C32: Dimensjonerende effekt likeretter
A33: Totalt effekttrekk - normaltdrift ICE | B33: =$B$22*D22+$B$23*D23+$B$24*D24+$B$26*D26+$B$27*D27+B25*D25+B28*D28+B29*D29 -> 3557 | C33: Dette er effekten vi forventer å bruke i gjennomsnitt
A34: Totalt effekttrekk - normaltdrift ICE | B34: =B33/1000 -> 3.557
A35: Totalt effekttrekk batteridrift inntil 10 min | B35: =$B$22*E22+$B$23*E23+$B$24*E24+$B$26*E26+$B$27*E27+B25*E25+B28*E28+B29*E29 -> 7628
A36: Totalt effekttrekk batteridrift etter 10 min | B36: =$B$22*F22+$B$23*F23+$B$24*F24+$B$26*F26+$B$27*F27+B25*F25+B28*F28+B29*F29 -> 3506
A37: Gjennomsnittlig effekt - 2 timer batteridrift | B37: =AVERAGE(B35,B36,B36,B36,B36,B36,B36,B36,B36,B36,B36,B36) -> 3849.5 | C37: Dimensjonerende effekt batterikapasitet
A38: Gjennomsnittlig effekt - 4 timer batteridrift | B38: =AVERAGE(B35,B36,B36,B36,B36,B36,B36,B36,B36,B36,B36,B36,B36,B36,B36,B36,B36,B36,B36,B36,B36,B36,B36,B36) -> 3677.75
A39: Behov batteristrenger (2t backupkrav): | B39: =ROUNDUP(Batteriutregninger!D3/4,0) -> 2 | C39: Behov batteristrenger (4t backupkrav): | E39: =ROUNDUP(Batteriutregninger!D4/4,0) -> 3 | F39: Behov 2t/4t i antall batteristrenger (1 stk streng = 4 stk batteri blokker)
A41: Energiforbruk pr dag | B41: =B34*24 -> 85.368
A42: Energiforbruk pr. måned | B42: =B34*8760/12 -> 2596.61
A43: Energiforbruk pr. år | B43: =B34*8760 -> 31159.32
A44: Energikostnad pr. dag | B44: =$B$17*B41 -> 0
A45: Energikostnad pr. måned | B45: =$B$17*B42 -> 0
A46: Energikostnad pr. år | B46: =$B$17*B43 -> 0
A49: Test av likeretter mot planlagt oppsett | B49: Tilgjengelig effekt >= Forespurt effekt | E49: Likeretterkalkulator flagger om batterier har kapasitet nødvendig kapasitet pr. time. Eksempel: Om batteribank har kapasitet til 2kW belastning pr. time vil kalkulator flagger grønt ved effekt i batteridrift <= 2kW
A50: Tilgjengelig effekt likeretter - normaltdrift | B50: 16000 | C50: =IF(B50>=B32,"JA","NEI") -> JA
A51: Tilgjengelig effekt - batteridrift pr. time | B51: 6434 | C51: =IF(B51>=B37,"JA","NEI") -> JA
A56: Beregning vern i likeretter basert på bestemt modelloppsett (brukes kun ved samlok)
...

Sheet Beregning vern LR
A1: Beregning LR-vern | B1: Standard vern (minimum) | G1: Dimmensjonerende effekt effekt [W] | I1: Dimensjonerende belastningsstrøm @38V ved RRH [A] | L1: Vern ice PDU - Basert på valgt konfig
L2: PDU vern - Modell S, M og L | N2: PDU vern ved 450Mhz
L3: PDU vern A | M3: PDU vern B | N3: PDU vern C
K4: Dimensjonerende effekt - 80% av maks [W] | L4: =L26 -> 4378 | M4: =N26 -> 3295.6 | N4: =N29 -> 0
B5: 1xC125A | C5: 1xC100A | D5: 1xC63A | G5: Total effekt | I5: Total laststrøm | K5: Dimmensjonerende strøm [A] @38V ved RRH | L5: =L4/38 -> 115.21053 | M5: =M4/38 -> 86.726316 | N5: =N4/38 -> 0
A6: Large | B6: 2 | G6: ='Effektkalkulator ice'!B32 -> 7628 | I6: =G6/38 -> 200.73684 | K6: Alternativ 1 (standard) | L6: =IF(AND($B$16>0,$B$17=0,$B$18=0),63,IF(L5>125,"> 125 A",125)) -> 125 | M6: =IF(AND($B$16>0,$B$17=0,$B$18=0),63,IF(M5>125,"> 125 A",125)) -> 125 | N6: =IF(B19>0,63,"N/A") -> N/A
A7: Large + 450 | B7: 2 | D7: 1 | K7: Alternativ 2 | L7: =IF(L$5<=63,63,IF(L$5<=125,125,"> 125 A")) -> 125 | M7: =IF(M$5<=63,63,IF(M$5<=125,125,"> 125 A")) -> 125 | N7: =IF(B19=0,"N/A",IF(N$5<=32,32,IF(N$5<=63,63,IF(B19>0,">63 A")))) -> N/A
A8: Medium | C8: 2 | K8: Alternativ 3 | L8: =IF(L$5<=32,32,IF(L$5<=63,63,IF(L$5<=80,80,IF(L$5<=100,100,IF(L$5<=125,125,"> 125 A"))))) -> 125 | M8: =IF(M$5<=32,32,IF(M$5<=63,63,IF(M$5<=80,80,IF(M$5<=100,100,IF(M$5<=125,125,"> 125 A"))))) -> 100 | N8: =IF(B19=0,"N/A",IF(N$5<=16,16,IF(N$5<=32,32,IF(N$5<=63,63,IF(N$5<=125,125,"> 63 A"))))) -> N/A
A9: Medium + 450 | C9: 2 | D9: 1 | G9: Fordelt effekt | I9: Fordelt laststrøm
A10: Small | D10: 2 | G10: Effekt eksklusive 450Mhz | H10: Effekt 450Mhz | I10: Laststrøm eksklusive 450Mhz | J10: Laststrøm 450Mhz
A11: Small + 450 | D11: 3 | G11: =G6-H11 -> 7628 | H11: ='Effektkalkulator ice'!B25*'Effektkalkulator ice'!E25 -> 0 | I11: =G11/38 -> 200.73684 | J11: =H11/38 -> 0
A14: ='Effektkalkulator ice'!A20 -> Input-data - Effektberegning | B14: ='Effektkalkulator ice'!B20 -> Kalkulator bruker ICE-effekter og beregner totalt ift. valgt sammensetning | C14: ='Effektkalkulator ice'!C20 -> 0 | D14: ='Effektkalkulator ice'!D20 -> 0 | F14: ='Effektkalkulator ice'!E20 -> 0 | G14: ='Effektkalkulator ice'!G20 -> 0 | H14: ='Effektkalkulator ice'!I20 -> 0 | K14: Vern PDU | L14: Effekter PDU vern A | N14: Effekter PDU vern B
A15: ='Effektkalkulator ice'!A21 -> Modellsite ice: LARGE (sitenivå) | B15: ='Effektkalkulator ice'!B21 -> Antall sektorer/ baseband | C15: ='Effektkalkulator ice'!C21 -> Effekt normaldrift "busy hour" | D15: ='Effektkalkulator ice'!D21 -> ICE normaltdrift snitteffekt | E15: ICE normaltdrift snitteffekt | F15: ='Effektkalkulator ice'!E21 -> Effekt normaltdrift 80% av maks | G15: ='Effektkalkulator ice'!F21 -> ICE Effekt batteridrift (450Mhz+800Mhz aktiv) 100% av maks | H15: ='Effektkalkulator ice'!I21 -> 0 | K15: #RRH Type | L15: Lavbånd RRH | M15: Aktiv N35 | N15: Mid-band RRH
A16: ='Effektkalkulator ice'!A22 -> Small | B16: ='Effektkalkulator ice'!B22 -> 0 | C16: ='Effektkalkulator ice'!C22 -> 571 | D16: ='Effektkalkulator ice'!D22 -> 301 | E16: 308 | F16: ='Effektkalkulator ice'!E22 -> 691.2 | G16: ='Effektkalkulator ice'!F22 -> 540 | H16: ='Effektkalkulator ice'!#REF! -> #REF! | K16: Antall RRH | L16: =B16 -> 0 | N16: 0
A17: ='Effektkalkulator ice'!A23 -> Medium | B17: ='Effektkalkulator ice'!B23 -> 0 | C17: ='Effektkalkulator ice'!C23 -> 1384 | D17: ='Effektkalkulator ice'!D23 -> 631 | E17: =E16+330 -> 638 | F17: ='Effektkalkulator ice'!E23 -> 1692.8 | G17: ='Effektkalkulator ice'!F23 -> 735 | H17: ='Effektkalkulator ice'!#REF! -> #REF! | L17: =B17 -> 0 | N17: =B17 -> 0
A18: ='Effektkalkulator ice'!A24 -> Large | B18: ='Effektkalkulator ice'!B24 -> 3 | C18: ='Effektkalkulator ice'!C24 -> 2134 | D18: ='Effektkalkulator ice'!D24 -> 1027 | E18: =E17+396 -> 1034 | F18: ='Effektkalkulator ice'!E24 -> 2384 | G18: ='Effektkalkulator ice'!F24 -> 1010 | H18: ='Effektkalkulator ice'!#REF! -> #REF! | L18: =B18 -> 3 | M18: =B18 -> 3 | N18: =B18 -> 3
A19: ='Effektkalkulator ice'!A25 -> Antall sektorer 450Mhz | B19: ='Effektkalkulator ice'!B25 -> 0 | C19: ='Effektkalkulator ice'!C25 -> 0 | D19: ='Effektkalkulator ice'!D25 -> 176 | E19: 176 | F19: ='Effektkalkulator ice'!E25 -> 280.8 | G19: ='Effektkalkulator ice'!F25 -> 351 | H19: ='Effektkalkulator ice'!#REF! -> #REF! | K19: Sum RRH | L19: =SUM(L16:L18) -> 3 | M19: =SUM(M16:M18) -> 3 | N19: =SUM(N16:N18) -> 3
A20: ='Effektkalkulator ice'!A26 -> Baseband 1 | B20: ='Effektkalkulator ice'!B26 -> 0 | C20: ='Effektkalkulator ice'!C26 -> 227 | D20: ='Effektkalkulator ice'!D26 -> 227 | E20: 227 | F20: ='Effektkalkulator ice'!E26 -> 227 | G20: ='Effektkalkulator ice'!F26 -> 227 | H20: ='Effektkalkulator ice'!#REF! -> #REF! | K20: Effekt RRH | L20: =848*0.8 -> 678.4 | M20: =877*0.8 -> 701.6 | N20: =1274*0.8 -> 1019.2
A21: ='Effektkalkulator ice'!A27 -> Baseband 2 (N35) | B21: ='Effektkalkulator ice'!B27 -> 1 | C21: ='Effektkalkulator ice'!C27 -> 376 | D21: ='Effektkalkulator ice'!D27 -> 376 | E21: 376 | F21: ='Effektkalkulator ice'!E27 -> 376 | G21: ='Effektkalkulator ice'!F27 -> 376 | H21: ='Effektkalkulator ice'!#REF! -> #REF! | K21: Sum effekt | L21: =L19*L20 -> 2035.2 | M21: =M19*M20 -> 2104.8 | N21: =N19*N20 -> 3057.6
A22: ='Effektkalkulator ice'!A28 -> Basestasjonsaksess (CSR) | B22: ='Effektkalkulator ice'!B28 -> 1 | C22: ='Effektkalkulator ice'!C28 -> 100 | D22: ='Effektkalkulator ice'!D28 -> 100 | E22: 200 | F22: ='Effektkalkulator ice'!E28 -> 100 | G22: ='Effektkalkulator ice'!F28 -> 100 | H22: ='Effektkalkulator ice'!#REF! -> #REF! | K22: Effekter NCR, Air Scale + RL (50%) | L22: =($B$20*$F$20+$B$21*$F$21+$B$22*$F$22+$B$23*$F$23)*0.5 -> 238 | N22: =($B$20*$F$20+$B$21*$F$21+$B$22*$F$22+$B$23*$F$23)*0.5 -> 238
A23: ='Effektkalkulator ice'!A29 -> Komplett radiolinje | B23: ='Effektkalkulator ice'!B29 -> 0 | C23: ='Effektkalkulator ice'!C29 -> 100 | D23: ='Effektkalkulator ice'!D29 -> 100 | E23: 200 | F23: ='Effektkalkulator ice'!E29 -> 100 | G23: ='Effektkalkulator ice'!F29 -> 100 | H23: ='Effektkalkulator ice'!#REF! -> #REF! | K23: Effekter NCR, Air Scale + RL (50%)
A24: ='Effektkalkulator ice'!A30 -> 0 | B24: ='Effektkalkulator ice'!B30 -> 0 | C24: ='Effektkalkulator ice'!C30 -> 0 | D24: ='Effektkalkulator ice'!D30 -> 0 | F24: ='Effektkalkulator ice'!E30 -> 0 | G24: ='Effektkalkulator ice'!G30 -> 0 | H24: ='Effektkalkulator ice'!#REF! -> #REF!
A25: ='Effektkalkulator ice'!A32 -> Maks effekt normaldrift (80% av maks) | B25: ='Effektkalkulator ice'!B32 -> 7628 | C25: ='Effektkalkulator ice'!C32 -> Dimensjonerende effekt likeretter | D25: ='Effektkalkulator ice'!D32 -> 0 | F25: ='Effektkalkulator ice'!E32 -> 0 | G25: ='Effektkalkulator ice'!G32 -> 0 | H25: ='Effektkalkulator ice'!I32 -> 0 | K25: Dimensjonerende effekt / type RRU | L25: =SUM(L21:L24) -> 2273.2 | M25: =SUM(M21:M24) -> 2104.8 | N25: =SUM(N21:N24) -> 3295.6
A26: ='Effektkalkulator ice'!A33 -> Totalt effekttrekk - normaltdrift ICE | B26: ='Effektkalkulator ice'!B33 -> 3557 | C26: ='Effektkalkulator ice'!C33 -> Dette er effekten vi forventer å bruke i gjennomsnitt | D26: ='Effektkalkulator ice'!D33 -> 0 | F26: ='Effektkalkulator ice'!E33 -> 0 | G26: ='Effektkalkulator ice'!G33 -> 0 | H26: ='Effektkalkulator ice'!I33 -> 0 | K26: Dimensjonerende effekt / Vern PDU | L26: =SUM(L25:M25) -> 4378 | N26: =N25 -> 3295.6
K27: Dimensjonerende laststrøm @38V | L27: =L26/38 -> 115.21053 | N27: =N26/38 -> 86.726316
K28: Effekt - Utstyr eks. 450Mhz | N28: =SUM(L26:N26) -> 7673.6
K29: Effekt - 450Mhz | N29: =B19*F19 -> 0
K30: Total effekt - alt utstyr | N30: =N28+N29 -> 7673.6
K31: Kontroll 1 | L31: =IF(N30=B25,"OK","FEIL") -> FEIL
K32: Kontroll 2 | L32: =IF(N30=SUM(L4:N4),"OK","FEIL") -> OK
K33: Kontroll 3 | L33: =IF(N30=G11+H11,"OK","FEIL") -> FEIL

Sheet Beregning AC vern
D1: Tilgjengelig effekt pr. LR-vern (230V) | F1: Belastningsgrad pr. LR-vern iht. nominell maks effekt (230V) | J1: Tilgjengelig effekt pr. LR-vern (207V) | L1: Belastningsgrad pr. LR-vern - nominell maks effekt (207V) | Q1: Dimmensjonerende fasespenning | S1: 215 | T1: Nettsystem | U1: ='Effektkalkulator ice'!B119 -> IT-230V | V1: Dimensjonerende laststrøm OV-vern (IT/TN) | Y1: ='Effektkalkulator ice'!B130 -> 32.224201
A2: Vern likeretter | B2: Vern faseleder | C2: Spenningssystem | D2: Effekt (nominell) [W] | E2: Effekt (i1-verdi) | F2: Small (max) | G2: Medium (max) | H2: Large (max) | I2: Full bestykning - 6 moduler = 12kW | J2: Effekt (nominell) [W] | K2: Effekt (i1-verdi) | L2: Small (max) | M2: Medium (max) | N2: Large (max) | O2: Full bestykning - 6 moduler = 12kW | Q2: Dimensjonerende laststrøm LR-vern | S2: ='Effektkalkulator ice'!B159 -> 16.112101 | T2: ='Effektkalkulator ice'!A120 -> Dimensjonerende Ik2pmin | U2: ='Effektkalkulator ice'!B120 -> 5 | V2: Eksisterende 3-fase vern/bryter AC fordeling huseier | Y2: ='Effektkalkulator ice'!B136 -> Ikke valgt
A3: 3x16A | B3: 16 | C3: IT-230V | D3: =B3*230*SQRT(3) -> 6373.947 | E3: =D3*1.13 -> 7202.5601 | F3: =$C$33/D3 -> 0.42093228 | G3: =$C$34/D3 -> 1.0205607 | H3: =$C$35/D3 -> 1.4766361 | I3: =12000/D3 -> 1.8826639 | J3: =B3*230*0.9*SQRT(3) -> 5736.5523 | K3: =J3*1.13 -> 6482.3041 | L3: =$C$33/J3 -> 0.46770253 | M3: =$C$34/J3 -> 1.1339564 | N3: =$C$35/J3 -> 1.6407067 | O3: =12000/J3 -> 2.0918488 | Q3: Eksisterende 3-fase vern likeretter (vern A) | S3: ='Effektkalkulator ice'!B150 -> 3x25A (IT) | V3: Maks fasestrøm eks. 3-fase vern/bryter AC fordeling huseier | Y3: =VLOOKUP(Y2,$AA$12:$AB$37,2,) -> #N/A
A4: 4x16A | B4: 16 | C4: TN-400V | D4: =B4*230*SQRT(3)*SQRT(3) -> 11040 | E4: =D4*1.13 -> 12475.2 | F4: =$C$33/D4 -> 0.24302536 | G4: =$C$34/D4 -> 0.58922101 | H4: =$C$35/D4 -> 0.85253623 | I4: =12000/D4 -> 1.0869565 | J4: =B4*230*0.9*SQRT(3)*SQRT(3) -> 9936 | K4: =J4*1.13 -> 11227.68 | L4: =$C$33/J4 -> 0.27002818 | M4: =$C$34/J4 -> 0.65469002 | N4: =$C$35/J4 -> 0.94726248 | O4: =12000/J4 -> 1.2077295 | Q4: Maks fasestrøm eks. 3-fase vern likeretter | S4: =VLOOKUP(S3,$AA$12:$AB$37,2,) -> 25 | V4: Eksisterende 3-fase vern/bryter AC fordeling ice | Y4: ='Effektkalkulator ice'!$B$141 -> 4x32A (TN)
A5: 3x20A | B5: 20 | C5: IT-230V | D5: =B5*230*SQRT(3) -> 7967.4337 | E5: =D5*1.13 -> 9003.2001 | F5: =$C$33/D5 -> 0.33674582 | G5: =$C$34/D5 -> 0.81644859 | H5: =$C$35/D5 -> 1.1813089 | I5: =12000/D5 -> 1.5061311 | J5: =B5*230*0.9*SQRT(3) -> 7170.6903 | K5: =J5*1.13 -> 8102.8801 | L5: =$C$33/J5 -> 0.37416202 | M5: =$C$34/J5 -> 0.9071651 | N5: =$C$35/J5 -> 1.3125654 | O5: =12000/J5 -> 1.673479 | Q5: Eksisterende 3-fase vern likeretter (vern B) | S5: ='Effektkalkulator ice'!B151 -> 3x25A (IT) | V5: Maks fasestrøm eks. 3-fase vern/bryter AC fordeling ice | Y5: =VLOOKUP(Y4,$AA$12:$AB$37,2,) -> 32
A6: 4x20A | B6: 20 | C6: TN-400V | D6: =B6*230*SQRT(3)*SQRT(3) -> 13800 | E6: =D6*1.13 -> 15594 | F6: =$C$33/D6 -> 0.19442029 | G6: =$C$34/D6 -> 0.47137681 | H6: =$C$35/D6 -> 0.68202899 | I6: =12000/D6 -> 0.86956522 | J6: =B6*230*0.9*SQRT(3)*SQRT(3) -> 12420 | K6: =J6*1.13 -> 14034.6 | L6: =$C$33/J6 -> 0.21602254 | M6: =$C$34/J6 -> 0.52375201 | N6: =$C$35/J6 -> 0.75780998 | O6: =12000/J6 -> 0.96618357 | Q6: Maks fasestrøm eks. 3-fase vern likeretter | S6: =VLOOKUP(S5,$AA$12:$AB$37,2,) -> 25 | V6: Standard OV-vern | Y6: {=_xlfn.IFS(U1="IT-230V",T15,U1="TN-400V",W14)} -> 3x32A (IT)
A7: 3x25A | B7: 25 | C7: IT-230V | D7: =B7*230*SQRT(3) -> 9959.2921 | E7: =D7*1.13 -> 11254 | F7: =$C$33/D7 -> 0.26939666 | G7: =$C$34/D7 -> 0.65315887 | H7: =$C$35/D7 -> 0.94504708 | I7: =12000/D7 -> 1.2049049 | J7: =B7*230*0.9*SQRT(3) -> 8963.3629 | K7: =J7*1.13 -> 10128.6 | L7: =$C$33/J7 -> 0.29932962 | M7: =$C$34/J7 -> 0.72573208 | N7: =$C$35/J7 -> 1.0500523 | O7: =12000/J7 -> 1.3387832 | Q7: ='Effektkalkulator ice'!A123 -> Lengde stigekabel | S7: ='Effektkalkulator ice'!$B$123 -> 50 | V7: Maks fasestrøm - standard OV-vern | Y7: =VLOOKUP(Y6,AA11:AC37,2,FALSE) -> 32
A8: 4x25A | B8: 25 | C8: TN-400V | D8: =B8*230*SQRT(3)*SQRT(3) -> 17250 | E8: =D8*1.13 -> 19492.5 | F8: =$C$33/D8 -> 0.15553623 | G8: =$C$34/D8 -> 0.37710145 | H8: =$C$35/D8 -> 0.54562319 | I8: =12000/D8 -> 0.69565217 | J8: =B8*230*0.9*SQRT(3)*SQRT(3) -> 15525 | K8: =J8*1.13 -> 17543.25 | L8: =$C$33/J8 -> 0.17281804 | M8: =$C$34/J8 -> 0.41900161 | N8: =$C$35/J8 -> 0.60624799 | O8: =12000/J8 -> 0.77294686 | Q8: ='Effektkalkulator ice'!A124 -> Eksisterende kabel type | S8: ='Effektkalkulator ice'!B124 -> 16mm2 Cu | V8: Alternativt 3-fase OV-vern | Y8: =R63 -> 3x40A (IT)
A9: 3x32A | B9: 32 | C9: IT-230V | D9: =B9*230*SQRT(3) -> 12747.894 | E9: =D9*1.13 -> 14405.12 | F9: =$C$33/D9 -> 0.21046614 | G9: =$C$34/D9 -> 0.51028037 | H9: =$C$35/D9 -> 0.73831803 | I9: =12000/D9 -> 0.94133196 | J9: =B9*230*0.9*SQRT(3) -> 11473.105 | K9: =J9*1.13 -> 12964.608 | L9: =$C$33/J9 -> 0.23385126 | M9: =$C$34/J9 -> 0.56697819 | N9: =$C$35/J9 -> 0.82035337 | O9: =12000/J9 -> 1.0459244 | V9: Maks fasestrøm - alternativt OV-vern | Y9: =VLOOKUP(Y8,AA13:AC39,2,FALSE) -> 40
A10: 4x32A | B10: 32 | C10: TN-400V | D10: =B10*230*SQRT(3)*SQRT(3) -> 22080 | E10: =D10*1.13 -> 24950.4 | F10: =$C$33/D10 -> 0.12151268 | G10: =$C$34/D10 -> 0.29461051 | H10: =$C$35/D10 -> 0.42626812 | I10: =12000/D10 -> 0.54347826 | J10: =B10*230*0.9*SQRT(3)*SQRT(3) -> 19872 | K10: =J10*1.13 -> 22455.36 | L10: =$C$33/J10 -> 0.13501409 | M10: =$C$34/J10 -> 0.32734501 | N10: =$C$35/J10 -> 0.47363124 | O10: =12000/J10 -> 0.60386473
A11: 3x40A | B11: 40 | C11: IT-230V | D11: =B11*230*SQRT(3) -> 15934.867 | E11: =D11*1.13 -> 18006.4 | F11: =$C$33/D11 -> 0.16837291 | G11: =$C$34/D11 -> 0.40822429 | H11: =$C$35/D11 -> 0.59065443 | I11: =12000/D11 -> 0.75306557 | J11: =B11*230*0.9*SQRT(3) -> 14341.381 | K11: =J11*1.13 -> 16205.76 | L11: =$C$33/J11 -> 0.18708101 | M11: =$C$34/J11 -> 0.45358255 | N11: =$C$35/J11 -> 0.6562827 | O11: =12000/J11 -> 0.83673952 | Q11: 1-fase vern IT/TN | R11: Fasestrøm | S11: =_xlfn.CONCAT("Effekt (",$S$1," V)") -> Effekt (215 V) | T11: 3-fase vern IT | U11: Fasestrøm | V11: =_xlfn.CONCAT("Effekt (",$S$1," V)") -> Effekt (215 V) | W11: 3-fase vern TN | X11: Fasestrøm | Y11: =_xlfn.CONCAT("Effekt (",$S$1," V)") -> Effekt (215 V) | AA11: 3-fase vern | AB11: Fasestrøm | AC11: =_xlfn.CONCAT("Effekt (",$S$1," V)") -> Effekt (215 V)
A12: 4x40A | B12: 40 | C12: TN-400V | D12: =B12*230*SQRT(3)*SQRT(3) -> 27600 | E12: =D12*1.13 -> 31188 | F12: =$C$33/D12 -> 0.097210145 | G12: =$C$34/D12 -> 0.23568841 | H12: =$C$35/D12 -> 0.34101449 | I12: =12000/D12 -> 0.43478261 | J12: =B12*230*0.9*SQRT(3)*SQRT(3) -> 24840 | K12: =J12*1.13 -> 28069.2 | L12: =$C$33/J12 -> 0.10801127 | M12: =$C$34/J12 -> 0.26187601 | N12: =$C$35/J12 -> 0.37890499 | O12: =12000/J12 -> 0.48309179 | Q12: 1x16A (IT/TN) | R12: 16 | S12: =R12*$S$1 -> 3440 | T12: 3x16A (IT) | U12: 16 | V12: =U12*SQRT(3)*$S$1 -> 5958.2548 | W12: 4x16A (TN) | X12: 16 | Y12: =X12*SQRT(3)*SQRT(3)*$S$1 -> 10320 | AA12: =T12 -> 3x16A (IT) | AB12: =U12 -> 16 | AC12: =V12 -> 5958.2548
A13: 3x63A | B13: 63 | C13: IT-230V | D13: =B13*230*SQRT(3) -> 25097.416 | E13: =D13*1.13 -> 28360.08 | F13: =$C$33/D13 -> 0.10690343 | G13: =$C$34/D13 -> 0.25919003 | H13: =$C$35/D13 -> 0.37501868 | I13: =12000/D13 -> 0.47813687 | J13: =B13*230*0.9*SQRT(3) -> 22587.675 | K13: =J13*1.13 -> 25524.072 | L13: =$C$33/J13 -> 0.11878159 | M13: =$C$34/J13 -> 0.28798892 | N13: =$C$35/J13 -> 0.41668743 | O13: =12000/J13 -> 0.53126319 | Q13: 1x20A (IT/TN) | R13: 20 | S13: =R13*$S$1 -> 4300 | T13: 3x20A (IT) | U13: 20 | V13: =U13*SQRT(3)*$S$1 -> 7447.8185 | W13: 4x20A (TN) | X13: 20 | Y13: =X13*SQRT(3)*SQRT(3)*$S$1 -> 12900 | AA13: =T13 -> 3x20A (IT) | AB13: =U13 -> 20 | AC13: =V13 -> 7447.8185
A14: 4x63A | B14: 63 | C14: TN-400V | D14: =B14*230*SQRT(3)*SQRT(3) -> 43470 | E14: =D14*1.13 -> 49121.1 | F14: =$C$33/D14 -> 0.061720727 | G14: =$C$34/D14 -> 0.14964343 | H14: =$C$35/D14 -> 0.21651714 | I14: =12000/D14 -> 0.27605245 | J14: =B14*230*0.9*SQRT(3)*SQRT(3) -> 39123 | K14: =J14*1.13 -> 44208.99 | L14: =$C$33/J14 -> 0.068578585 | M14: =$C$34/J14 -> 0.16627048 | N14: =$C$35/J14 -> 0.2405746 | O14: =12000/J14 -> 0.30672494 | Q14: 1x25A (IT/TN) | R14: 25 | S14: =R14*$S$1 -> 5375 | T14: 3x25A (IT) | U14: 25 | V14: =U14*SQRT(3)*$S$1 -> 9309.7731 | W14: 4x25A (TN) | X14: 25 | Y14: =X14*SQRT(3)*SQRT(3)*$S$1 -> 16125 | AA14: =T14 -> 3x25A (IT) | AB14: =U14 -> 25 | AC14: =V14 -> 9309.7731
Q15: 1x32A (IT/TN) | R15: 32 | S15: =R15*$S$1 -> 6880 | T15: 3x32A (IT) | U15: 32 | V15: =U15*SQRT(3)*$S$1 -> 11916.51 | W15: 4x32A (TN) | X15: 32 | Y15: =X15*SQRT(3)*SQRT(3)*$S$1 -> 20640 | AA15: =T15 -> 3x32A (IT) | AB15: =U15 -> 32 | AC15: =V15 -> 11916.51
T16: 3x40A (IT) | U16: 40 | V16: =U16*SQRT(3)*$S$1 -> 14895.637 | W16: 4x40A (TN) | X16: 40 | Y16: =X16*SQRT(3)*SQRT(3)*$S$1 -> 25800 | AA16: =T16 -> 3x40A (IT) | AB16: =U16 -> 40 | AC16: =V16 -> 14895.637
D17: Tilgjengelig nominell effekt (230V) [W] | E17: Belastningsgrad 24kW fullbestykket LR mot OV | T17: 3x50A (IT) | U17: 50 | V17: =U17*SQRT(3)*$S$1 -> 18619.546 | W17: 4x50A (TN) | X17: 50 | Y17: =X17*SQRT(3)*SQRT(3)*$S$1 -> 32250 | AA17: =T17 -> 3x50A (IT) | AB17: =U17 -> 50 | AC17: =V17 -> 18619.546
A18: Vern OV | B18: Vern faseleder | C18: Spenningssystem | E18: 230V fasespenning | F18: 207V fasespenning | G18: Kommentar Håvard (mulig vi skyter litt høyt her...) | T18: 3x63A (IT) | U18: 63 | V18: =U18*SQRT(3)*$S$1 -> 23460.628 | W18: 4x63A (TN) | X18: 63 | Y18: =X18*SQRT(3)*SQRT(3)*$S$1 -> 40635 | AA18: =T18 -> 3x63A (IT) | AB18: =U18 -> 63 | AC18: =V18 -> 23460.628
A19: 3x25A | B19: 25 | C19: IT-230V | D19: =B19*230*SQRT(3) -> 9959.2921 | E19: =24000/D19 -> 2.4098098 | F19: =24000/(D19*0.9) -> 2.6775665 | T19: 3x80A (IT) | U19: 80 | V19: =U19*SQRT(3)*$S$1 -> 29791.274 | W19: 4x80A (TN) | X19: 80 | Y19: =X19*SQRT(3)*SQRT(3)*$S$1 -> 51600 | AA19: =T19 -> 3x80A (IT) | AB19: =U19 -> 80 | AC19: =V19 -> 29791.274
A20: 3x25A | B20: 25 | C20: TN-400V | D20: =B20*230*SQRT(3)*SQRT(3) -> 17250 | E20: =24000/D20 -> 1.3913043 | F20: =24000/(D20*0.9) -> 1.5458937 | T20: Lastbryter 3x32A (IT) | U20: 32 | V20: =U20*SQRT(3)*$S$1 -> 11916.51 | W20: Lastbryter 4x32A (TN) | X20: 32 | Y20: =X20*SQRT(3)*SQRT(3)*$S$1 -> 20640 | AA20: =T20 -> Lastbryter 3x32A (IT) | AB20: =U20 -> 32 | AC20: =V20 -> 11916.51
A21: 3x32A | B21: 32 | C21: IT-230V | D21: =B21*230*SQRT(3) -> 12747.894 | E21: =24000/D21 -> 1.8826639 | F21: =24000/(D21*0.9) -> 2.0918488 | T21: Lastbryter 3x40A (IT) | U21: 40 | V21: =U21*SQRT(3)*$S$1 -> 14895.637 | W21: Lastbryter 4x40A (TN) | X21: 40 | Y21: =X21*SQRT(3)*SQRT(3)*$S$1 -> 25800 | AA21: =T21 -> Lastbryter 3x40A (IT) | AB21: =U21 -> 40 | AC21: =V21 -> 14895.637
A22: 3x32A | B22: 32 | C22: TN-400V | D22: =B22*230*SQRT(3)*SQRT(3) -> 22080 | E22: =24000/D22 -> 1.0869565 | F22: =24000/(D22*0.9) -> 1.2077295 | T22: Lastbryter 3x50A (IT) | U22: 50 | V22: =U22*SQRT(3)*$S$1 -> 18619.546 | W22: Lastbryter 4x50A (TN) | X22: 50 | Y22: =X22*SQRT(3)*SQRT(3)*$S$1 -> 32250 | AA22: =T22 -> Lastbryter 3x50A (IT) | AB22: =U22 -> 50 | AC22: =V22 -> 18619.546
A23: 3x40A | B23: 40 | C23: IT-230V | D23: =B23*230*SQRT(3) -> 15934.867 | E23: =24000/D23 -> 1.5061311 | F23: =24000/(D23*0.9) -> 1.673479 | T23: Lastbryter 3x63A (IT) | U23: 63 | V23: =U23*SQRT(3)*$S$1 -> 23460.628 | W23: Lastbryter 4x63A (TN) | X23: 63 | Y23: =X23*SQRT(3)*SQRT(3)*$S$1 -> 40635 | AA23: =T23 -> Lastbryter 3x63A (IT) | AB23: =U23 -> 63 | AC23: =V23 -> 23460.628
A24: 3x40A | B24: 40 | C24: TN-400V | D24: =B24*230*SQRT(3)*SQRT(3) -> 27600 | E24: =24000/D24 -> 0.86956522 | F24: =24000/(D24*0.9) -> 0.96618357 | G24: Pri 2 for TN-nett, dersom 3x63 drar opp kostnad vesentlig | T24: Lastbryter 3x80A (IT) | U24: 80 | V24: =U24*SQRT(3)*$S$1 -> 29791.274 | W24: Lastbryter 4x80A (TN) | X24: 80 | Y24: =X24*SQRT(3)*SQRT(3)*$S$1 -> 51600 | AA24: =T24 -> Lastbryter 3x80A (IT) | AB24: =U24 -> 80 | AC24: =V24 -> 29791.274
A25: 3x63A | B25: 63 | C25: IT-230V | D25: =B25*230*SQRT(3) -> 25097.416 | E25: =24000/D25 -> 0.95627374 | F25: =24000/(D25*0.9) -> 1.0625264 | G25: Pri 2 IT-nett, dersom 3x80A drar opp kostnad vesentlig | Q25: Kapasitet Likeretter | R25: Dimensjonerende Kapasitet (n-1) | S25: Maks antall moduler | AA25: =W12 -> 4x16A (TN) | AB25: =X12 -> 16 | AC25: =Y12 -> 10320
A26: 3x63A | B26: 63 | C26: TN-400V | D26: =B26*230*SQRT(3)*SQRT(3) -> 43470 | E26: =24000/D26 -> 0.5521049 | F26: =24000/(D26*0.9) -> 0.61344989 | G26: Pri 1 for TN-nett | Q26: Ikke valgt | AA26: =W13 -> 4x20A (TN) | AB26: =X13 -> 20 | AC26: =Y13 -> 12900
A27: 3x80A | B27: 80 | C27: IT-230V | D27: =B27*230*SQRT(3) -> 31869.735 | E27: =24000/D27 -> 0.75306557 | F27: =24000/(D27*0.9) -> 0.83673952 | G27: Pri 1 IT-nett | Q27: Eltek FP2 - 8kW | R27: =8000-2000 -> 6000 | S27: 4 | AA27: =W14 -> 4x25A (TN) | AB27: =X14 -> 25 | AC27: =Y14 -> 16125
A28: 3x80A | B28: 80 | C28: TN-400V | D28: =B28*230*SQRT(3)*SQRT(3) -> 55200 | E28: =24000/D28 -> 0.43478261 | F28: =24000/(D28*0.9) -> 0.48309179 | Q28: Eltek FP2 - 16kW | R28: =16000-2000 -> 14000 | S28: 8 | AA28: =W15 -> 4x32A (TN) | AB28: =X15 -> 32 | AC28: =Y15 -> 20640
Q29: Eltek FP2 - 24kW | R29: =24000-2000 -> 22000 | S29: 12 | AA29: =W16 -> 4x40A (TN) | AB29: =X16 -> 40 | AC29: =Y16 -> 25800
AA30: =W17 -> 4x50A (TN) | AB30: =X17 -> 50 | AC30: =Y17 -> 32250
Q31: Variasjoner LR-vern | R31: Valg av LR-vern | AA31: =W18 -> 4x63A (TN) | AB31: =X18 -> 63 | AC31: =Y18 -> 40635
A32: Band | B32: Average Power [W] | C32: Max Power [W] | D32: Modules | E32: Total Modules | Q32: Ikke valgt | R32: Relevante vern | S32: Tilhørende fasestrøm | T32: Laststrøm fase - LR-vern | U32: Vern OK? | V32: Eksisterende LR vern | W32: Tilhørende fasestrøm | X32: Vern ok? | AA32: =W19 -> 4x80A (TN) | AB32: =X19 -> 80 | AC32: =Y19 -> 51600
A33: 700/800 | B33: 1678 | C33: 2683 | D33: 2+1 | E33: 3 | Q33: =Q12 -> 1x16A (IT/TN) | R33: Ikke valgt | AA33: =W20 -> Lastbryter 4x32A (TN) | AB33: =X20 -> 32 | AC33: =Y20 -> 20640
A34: 700/800/1800/2100 | B34: 3856 | C34: 6505 | D34: 4+1 | E34: 5 | Q34: =Q13 -> 1x20A (IT/TN) | R34: =IF($U$1="IT-230V",T12,IF($U$1="TN-400V",W12,"")) -> 3x16A (IT) | S34: =VLOOKUP(R34,$AA$11:$AC$37,2,FALSE) -> 16 | T34: =$S$2 -> 16.112101 | U34: =IF(S34>=T34,TRUE,FALSE) -> FALSE | V34: =$S$3 -> 3x25A (IT) | W34: =$S$4 -> 25 | X34: =IF(W34>=T34,TRUE,FALSE) -> TRUE | AA34: =W21 -> Lastbryter 4x40A (TN) | AB34: =X21 -> 40 | AC34: =Y21 -> 25800
A35: 700/800/1800/2100/3600 | B35: 5995 | C35: 9412 | D35: 5+1 | E35: 6 | Q35: =Q14 -> 1x25A (IT/TN) | R35: =IF($U$1="IT-230V",T13,IF($U$1="TN-400V",W13,"")) -> 3x20A (IT) | S35: =VLOOKUP(R35,$AA$11:$AC$37,2,FALSE) -> 20 | T35: =$S$2 -> 16.112101 | U35: =IF(S35>=T35,TRUE,FALSE) -> TRUE | V35: =S5 -> 3x25A (IT) | W35: =$S$6 -> 25 | X35: =IF(W35>=T35,TRUE,FALSE) -> TRUE | AA35: =W22 -> Lastbryter 4x50A (TN) | AB35: =X22 -> 50 | AC35: =Y22 -> 32250
Q36: =Q15 -> 1x32A (IT/TN) | R36: =IF($U$1="IT-230V",T14,IF($U$1="TN-400V",W14,"")) -> 3x25A (IT) | S36: =VLOOKUP(R36,$AA$11:$AC$37,2,FALSE) -> 25 | T36: =$S$2 -> 16.112101 | U36: =IF(S36>=T36,TRUE,FALSE) -> TRUE | AA36: =W23 -> Lastbryter 4x63A (TN) | AB36: =X23 -> 63 | AC36: =Y23 -> 40635
Q37: =T12 -> 3x16A (IT) | R37: =IF($U$1="IT-230V",T15,IF($U$1="TN-400V",W15,"")) -> 3x32A (IT) | S37: =VLOOKUP(R37,$AA$11:$AC$37,2,FALSE) -> 32 | T37: =$S$2 -> 16.112101 | U37: =IF(S37>=T37,TRUE,FALSE) -> TRUE | AA37: =W24 -> Lastbryter 4x80A (TN) | AB37: =X24 -> 80 | AC37: =Y24 -> 51600
Q38: =T13 -> 3x20A (IT)
Q39: =T14 -> 3x25A (IT)
Q40: =T15 -> 3x32A (IT)
...

Sheet Kabellengder AC - samlet
A1: ='Effektkalkulator ice'!A134 -> AC fordeling huseier | E1: Fasestrøm | F1: Input data | K1: ='Effektkalkulator ice'!A139 -> AC fordeling ICE | N1: Fasestrøm | P1: Alternativer vern-fabrikat | Q1: Ontervaller Ik_min | R1: Type vern | S1: Intervaller Ik_maks | T1: Type vern
A2: ='Effektkalkulator ice'!A135 -> Eksisterende OV-vern (fabrikat) | C2: ='Effektkalkulator ice'!B135 -> Eaton elementautomat | F2: Nettsystem | J2: ='Effektkalkulator ice'!B119 -> IT-230V | K2: ='Effektkalkulator ice'!A140 -> Eksisterende OV-vern (fabrikat) | M2: ='Effektkalkulator ice'!B140 -> Eaton elementautomat | P2: Ikke valgt | Q2: 0.25 | S2: 9.9 | T2: Elementautomat
A3: ='Effektkalkulator ice'!A136 -> Eksisterende OV-vern (størrelse) | C3: ='Beregning AC vern'!Y2 -> Ikke valgt | E3: ='Beregning AC vern'!Y3 -> #N/A | F3: ='Effektkalkulator ice'!A120 -> Dimensjonerende Ik2pmin | J3: ='Effektkalkulator ice'!B120 -> 5 | K3: ='Effektkalkulator ice'!A141 -> Eksisterende OV-vern (størrelse) | M3: ='Beregning AC vern'!Y4 -> 4x32A (TN) | N3: ='Beregning AC vern'!Y5 -> 32 | P3: Eaton elementautomat | Q3: 0.5 | S3: 19.9 | T3: Effektbryter
A4: ='Effektkalkulator ice'!A137 -> Standard OV-vern | C4: ='Effektkalkulator ice'!B137 -> 3x40A (IT) | E4: ='Beregning AC vern'!$Y$7 -> 32 | F4: ='Effektkalkulator ice'!A121 -> Dimensjonerende Ik3pmaks | J4: ='Effektkalkulator ice'!B121 -> 5 | K4: ='Effektkalkulator ice'!A142 -> Standard vern | M4: ='Effektkalkulator ice'!B142 -> Eaton 3x63A (IT) | N4: ='Beregning AC vern'!$Y$7 -> 32 | P4: Schneider elementautomat | Q4: 1
A5: ='Effektkalkulator ice'!A138 -> Standard OV-vern | C5: ='Effektkalkulator ice'!B138 -> Eaton 3x40A (IT) | E5: ='Beregning AC vern'!$Y$9 -> 40 | F5: ='Effektkalkulator ice'!A122 -> Plassering OV-vern | J5: ='Effektkalkulator ice'!B122 -> AC fordeling huseier | K5: ='Effektkalkulator ice'!A143 -> Alternativt OV-vern | M5: ='Effektkalkulator ice'!B143 -> Eaton 3x40A (IT) | N5: ='Beregning AC vern'!$Y$9 -> 40 | P5: Schneider effektbryter | Q5: 2
A6: Gjenbruk ok for Eaton vern | F6: ='Beregning AC vern'!V1 -> Dimensjonerende laststrøm OV-vern (IT/TN) | J6: ='Beregning AC vern'!Y1 -> 32.224201 | K6: Gjenbruk ok for Eaton vern | P6: Annen elementautomat | Q6: 5
A7: Gjenbruk ok for Schneider vern | F7: ='Effektkalkulator ice'!A123 -> Lengde stigekabel | J7: ='Beregning AC vern'!S7 -> 50 | K7: Gjenbruk ok for Schneider vern | P7: Annen effektbryter | Q7: 8.5
A8: Gjenbruk ok for andre vern | F8: ='Effektkalkulator ice'!A124 -> Eksisterende kabel type | J8: ='Beregning AC vern'!S8 -> 16mm2 Cu | K8: Gjenbruk ok for andre vern | P8: Kortslutningsvern | Q8: 10 | R8: Effektbryter
F9: Maks kabellengde eksisterende vern | J9: {=IF(COUNTA(L39:L356=1),SUM(L39:L356),"ERROR")} -> #N/A | Q9: 15 | R9: Effektbryter
F10: Gjenbruk av kabel | J10: =IF(J9>=J7,TRUE,FALSE) -> #N/A
A18: =A1 -> AC fordeling huseier
A19: Nettsystem | B19: Vernleverandør | C19: Vern (A) | D19: Ikpmaks (kA) | E19: Ikpmin (kA) | F19: Tversnitt | G19: Uttak | H19: Nytt tverrsnitt | I19: Ledertype | J19: Kabellengde [m] | K19: Antall aktuelle kabler | L19: Kommentar
A20: =$J$2 -> IT-230V | B20: =$C$2 -> Eaton elementautomat | C20: =$E$3 -> #N/A | D20: {=_xlfn.IFS($J$4<=9.9,9.9,$J$4>9.9,19.9)} -> 9.9 | E20: =VLOOKUP($J$3,$Q$1:$Q$9,1,TRUE) -> 5 | F20: =$J$8 -> 16mm2 Cu | G20: =MID(F20,1,2) -> 16 | H20: {=IF(MIN(FIND({0,1,2,3,4,5,6,7,8,9},$G$20&"_0123456789"))>LEN($G$20), "",SUMPRODUCT(MID(0&$G$20,LARGE(INDEX(ISNUMBER(--MID($G$20,ROW(INDIRECT("$1:$"&LEN($G$20))),1))*ROW(INDIRECT("$1:$"&LEN($G$20))),0),ROW(INDIRECT("$1:$"&LEN($G$20))))+1,1)*10^ROW(INDIRECT("$1:$"&LEN($G$20)))/10))} -> 16 | I20: =MID($F$20,6,3) -> Cu | J20: =_xlfn.IFNA(VLOOKUP(TRUE,K38:L356,2,TRUE),"Ingen treff") -> Ingen treff | K20: =$L$37 -> 0 | L20: Input data eks. vern
A21: =$J$2 -> IT-230V | B21: =IF($J$4<=$S$2,$P$3,$P$5) -> Eaton elementautomat | C21: ='Beregning AC vern'!$Y$7 -> 32 | D21: =IF($J$4<=9.9,9.9,IF($J$4>9.9,19.9,"")) -> 9.9 | E21: =VLOOKUP($J$3,$Q$1:$Q$9,1,TRUE) -> 5 | F21: =VLOOKUP(TRUE,$M$38:$O$356,3,) -> 10mm2 Cu | G21: =MID(F21,1,2) -> 10 | H21: {=IF(MIN(FIND({0,1,2,3,4,5,6,7,8,9},$G$21&"_0123456789"))>LEN($G$21), "",SUMPRODUCT(MID(0&$G$21,LARGE(INDEX(ISNUMBER(--MID($G$21,ROW(INDIRECT("$1:$"&LEN($G$21))),1))*ROW(INDIRECT("$1:$"&LEN($G$21))),0),ROW(INDIRECT("$1:$"&LEN($G$21))))+1,1)*10^ROW(INDIRECT("$1:$"&LEN($G$21)))/10))} -> 10 | I21: =MID(F21,6,3) -> Cu | J21: =_xlfn.IFNA(VLOOKUP(TRUE,$M$38:$O$356,2,),"Ingen treff") -> 81 | K21: =COUNT($N$39:$N$356) -> 3 | L21: Input data - standard vern
A22: =$J$2 -> IT-230V | B22: =IF($J$4<=$S$2,$P$3,$P$5) -> Eaton elementautomat | C22: ='Beregning AC vern'!$Y$7 -> 32 | D22: =IF($J$4<=9.9,9.9,IF($J$4>9.9,19.9,"")) -> 9.9 | E22: =VLOOKUP($J$3,$Q$1:$Q$9,1,TRUE) -> 5 | F22: =VLOOKUP(TRUE,$M$38:$O$356,3,) -> 10mm2 Cu | G22: =MID(F22,1,2) -> 10 | H22: {=IF(MIN(FIND({0,1,2,3,4,5,6,7,8,9},$G$21&"_0123456789"))>LEN($G$21), "",SUMPRODUCT(MID(0&$G$21,LARGE(INDEX(ISNUMBER(--MID($G$21,ROW(INDIRECT("$1:$"&LEN($G$21))),1))*ROW(INDIRECT("$1:$"&LEN($G$21))),0),ROW(INDIRECT("$1:$"&LEN($G$21))))+1,1)*10^ROW(INDIRECT("$1:$"&LEN($G$21)))/10))} -> 10 | I22: =MID(F22,6,3) -> Cu | J22: =VLOOKUP(TRUE,$M$38:$O$356,2,) -> 81 | K22: =COUNT($N$39:$N$356) -> 3 | L22: Input data - standard vern
A23: =$J$2 -> IT-230V | B23: =IF($J$4<=$S$2,$P$3,$P$5) -> Eaton elementautomat | C23: ='Beregning AC vern'!$Y$7 -> 32 | D23: =IF($J$4<=9.9,9.9,IF($J$4>9.9,19.9,"")) -> 9.9 | E23: =VLOOKUP($J$3,$Q$1:$Q$9,1,TRUE) -> 5 | F23: =VLOOKUP(TRUE,$M$38:$O$356,3,) -> 10mm2 Cu | G23: =MID(F23,1,2) -> 10 | H23: {=IF(MIN(FIND({0,1,2,3,4,5,6,7,8,9},$G$21&"_0123456789"))>LEN($G$21), "",SUMPRODUCT(MID(0&$G$21,LARGE(INDEX(ISNUMBER(--MID($G$21,ROW(INDIRECT("$1:$"&LEN($G$21))),1))*ROW(INDIRECT("$1:$"&LEN($G$21))),0),ROW(INDIRECT("$1:$"&LEN($G$21))))+1,1)*10^ROW(INDIRECT("$1:$"&LEN($G$21)))/10))} -> 10 | I23: =MID(F23,6,3) -> Cu | J23: =VLOOKUP(TRUE,$M$38:$O$356,2,) -> 81 | K23: =COUNT($N$39:$N$356) -> 3 | L23: Input data - standard vern
A24: =$J$2 -> IT-230V | B24: =IF($J$4<=$S$2,$P$3,$P$5) -> Eaton elementautomat | C24: ='Beregning AC vern'!$Y$9 -> 40 | D24: =IF($J$4<=9.9,9.9,IF($J$4>9.9,19.9,"")) -> 9.9 | E24: =VLOOKUP($J$3,$Q$1:$Q$9,1,TRUE) -> 5 | F24: =VLOOKUP(TRUE,$P$38:$R$356,3,) -> 16mm2 Cu | G24: =MID(F24,1,2) -> 16 | H24: {=IF(MIN(FIND({0,1,2,3,4,5,6,7,8,9},$G$24&"_0123456789"))>LEN($G$24), "",SUMPRODUCT(MID(0&$G$24,LARGE(INDEX(ISNUMBER(--MID($G$24,ROW(INDIRECT("$1:$"&LEN($G$24))),1))*ROW(INDIRECT("$1:$"&LEN($G$24))),0),ROW(INDIRECT("$1:$"&LEN($G$24))))+1,1)*10^ROW(INDIRECT("$1:$"&LEN($G$24)))/10))} -> 16 | I24: =MID(F24,6,3) -> Cu | J24: =_xlfn.IFNA(VLOOKUP(TRUE,$P$38:$R$356,2,),"Ingen treff") -> 103 | K24: =COUNT($Q$39:$Q$356) -> 3 | L24: Input data - alternativt vern
A25: =$J$2 -> IT-230V | B25: =IF($J$4<=$S$2,$P$3,$P$5) -> Eaton elementautomat | C25: ='Beregning AC vern'!$Y$9 -> 40 | D25: =IF($J$4<=9.9,9.9,IF($J$4>9.9,19.9,"")) -> 9.9 | E25: =VLOOKUP($J$3,$Q$1:$Q$9,1,TRUE) -> 5 | F25: =VLOOKUP(TRUE,$P$38:$R$356,3,) -> 16mm2 Cu | G25: =MID(F25,1,2) -> 16 | H25: {=IF(MIN(FIND({0,1,2,3,4,5,6,7,8,9},$G$24&"_0123456789"))>LEN($G$24), "",SUMPRODUCT(MID(0&$G$24,LARGE(INDEX(ISNUMBER(--MID($G$24,ROW(INDIRECT("$1:$"&LEN($G$24))),1))*ROW(INDIRECT("$1:$"&LEN($G$24))),0),ROW(INDIRECT("$1:$"&LEN($G$24))))+1,1)*10^ROW(INDIRECT("$1:$"&LEN($G$24)))/10))} -> 16 | I25: =MID(F25,6,3) -> Cu | J25: =VLOOKUP(TRUE,$P$38:$R$356,2,) -> 103 | K25: =COUNT($Q$39:$Q$356) -> 3 | L25: Input data - alternativt vern
A26: =$J$2 -> IT-230V | B26: =IF($J$4<=$S$2,$P$3,$P$5) -> Eaton elementautomat | C26: ='Beregning AC vern'!$Y$9 -> 40 | D26: =IF($J$4<=9.9,9.9,IF($J$4>9.9,19.9,"")) -> 9.9 | E26: =VLOOKUP($J$3,$Q$1:$Q$9,1,TRUE) -> 5 | F26: =VLOOKUP(TRUE,$P$38:$R$356,3,) -> 16mm2 Cu | G26: =MID(F26,1,2) -> 16 | H26: {=IF(MIN(FIND({0,1,2,3,4,5,6,7,8,9},$G$24&"_0123456789"))>LEN($G$24), "",SUMPRODUCT(MID(0&$G$24,LARGE(INDEX(ISNUMBER(--MID($G$24,ROW(INDIRECT("$1:$"&LEN($G$24))),1))*ROW(INDIRECT("$1:$"&LEN($G$24))),0),ROW(INDIRECT("$1:$"&LEN($G$24))))+1,1)*10^ROW(INDIRECT("$1:$"&LEN($G$24)))/10))} -> 16 | I26: =MID(F26,6,3) -> Cu | J26: =VLOOKUP(TRUE,$P$38:$R$356,2,) -> 103 | K26: =COUNT($Q$39:$Q$356) -> 3 | L26: Input data - alternativt vern
A28: =K1 -> AC fordeling ICE
A38: Nettsystem | B38: Vernleverandør | C38: Vern (A) | D38: Ikpmaks (kA) | E38: Ikpmin (kA) | F38: Tversnitt | H38: Nytt tverrsnitt | I38: Ledertype | J38: Kabellengde [m] | K38: Test (match kol. A-F) | L38: Maks kabellengde eks. vern | M38: Test (match kol. A-E) | N38: Maks kabellengde standard vern | O38: Tilhørende tverrsnitt/leder | P38: Test (match kol. A-E) | Q38: Maks kabellengde alternativt vern | R38: Tilhørende tverrsnitt/leder | V38: Oversikt IT-anlegg 230V | X38: Kortslutningstrømmer: | AA38: Ikpmaks | AB38: Ikpmin
A39: IT-230V | B39: Schneider elementautomat | C39: 25 | D39: 9.9 | E39: 0.25 | F39: 6mm2 Cu | H39: 6 | I39: =MID(F39,6,3) -> Cu | J39: 15 | K39: =IF(AND($A$20=$A39,$B$20=$B39,$C$20=$C39,$D$20=$D39,$E$20=$E39,$F$20=$F39),TRUE,"") -> #N/A | L39: =IF(K39=TRUE,J39,"") -> #N/A | M39: =IF(AND($A$21=$A39,$B$21=$B39,$C$21=$C39,$D$21=$D39,$E$21=$E39,$J$7<=J39),TRUE,"") | N39: =IF(M39=TRUE,J39,"") | O39: =IF(M39=TRUE,F39,"") | P39: =IF(AND($C$24=50,'Beregning AC vern'!U1="IT-230V"),FALSE,IF(AND($A$24=$A39,$B$24=$B39,$C$24=$C39,$D$24=$D39,$E$24=$E39),TRUE,"")) | Q39: =IF(P39=TRUE,J39,IF(P39=FALSE,FALSE)) -> FALSE | R39: =IF(P39=TRUE,F39,IF(P39=FALSE,"Data mangler")) -> FALSE | V39: vern i H.F for hovedkabler | AA39: 9,9kA | AB39: 0,25-8,5kA
A40: IT-230V | B40: Schneider elementautomat | C40: 25 | D40: 9.9 | E40: 0.25 | F40: 10mm2 Cu | H40: 10 | I40: =MID(F40,6,3) -> Cu | J40: 25 | K40: =IF(AND($A$20=$A40,$B$20=$B40,$C$20=$C40,$D$20=$D40,$E$20=$E40,$F$20=$F40),TRUE,"") -> #N/A | L40: =IF(K40=TRUE,J40,"") -> #N/A | M40: =IF(AND($A$21=$A40,$B$21=$B40,$C$21=$C40,$D$21=$D40,$E$21=$E40,$J$7<=J40),TRUE,"") | N40: =IF(M40=TRUE,J40,"") | O40: =IF(M40=TRUE,F40,"") | P40: =IF(AND($C$24=50,'Beregning AC vern'!U2="IT-230V"),FALSE,IF(AND($A$24=$A40,$B$24=$B40,$C$24=$C40,$D$24=$D40,$E$24=$E40),TRUE,"")) | Q40: =IF(P40=TRUE,J40,IF(P40=FALSE,FALSE)) -> FALSE | R40: =IF(P40=TRUE,F40,IF(P40=FALSE,"Data mangler")) -> FALSE | V40: Schneider elementautomat
A41: IT-230V | B41: Schneider elementautomat | C41: 25 | D41: 9.9 | E41: 0.25 | F41: 25mm2 Al | H41: 25 | I41: =MID(F41,6,3) -> Al | J41: 38 | K41: =IF(AND($A$20=$A41,$B$20=$B41,$C$20=$C41,$D$20=$D41,$E$20=$E41,$F$20=$F41),TRUE,"") -> #N/A | L41: =IF(K41=TRUE,J41,"") -> #N/A | M41: =IF(AND($A$21=$A41,$B$21=$B41,$C$21=$C41,$D$21=$D41,$E$21=$E41,$J$7<=J41),TRUE,"") | N41: =IF(M41=TRUE,J41,"") | O41: =IF(M41=TRUE,F41,"") | P41: =IF(AND($C$24=50,'Beregning AC vern'!U3="IT-230V"),FALSE,IF(AND($A$24=$A41,$B$24=$B41,$C$24=$C41,$D$24=$D41,$E$24=$E41),TRUE,"")) | Q41: =IF(P41=TRUE,J41,IF(P41=FALSE,FALSE)) -> FALSE | R41: =IF(P41=TRUE,F41,IF(P41=FALSE,"Data mangler")) -> FALSE
A42: IT-230V | B42: Schneider elementautomat | C42: 25 | D42: 9.9 | E42: 0.25 | F42: 50mm2 Al | H42: 50 | I42: =MID(F42,6,3) -> Al | J42: 69 | K42: =IF(AND($A$20=$A42,$B$20=$B42,$C$20=$C42,$D$20=$D42,$E$20=$E42,$F$20=$F42),TRUE,"") -> #N/A | L42: =IF(K42=TRUE,J42,"") -> #N/A | M42: =IF(AND($A$21=$A42,$B$21=$B42,$C$21=$C42,$D$21=$D42,$E$21=$E42,$J$7<=J42),TRUE,"") | N42: =IF(M42=TRUE,J42,"") | O42: =IF(M42=TRUE,F42,"") | P42: =IF(AND($C$24=50,'Beregning AC vern'!U4="IT-230V"),FALSE,IF(AND($A$24=$A42,$B$24=$B42,$C$24=$C42,$D$24=$D42,$E$24=$E42),TRUE,"")) | Q42: =IF(P42=TRUE,J42,IF(P42=FALSE,FALSE)) -> FALSE | R42: =IF(P42=TRUE,F42,IF(P42=FALSE,"Data mangler")) -> FALSE
A43: IT-230V | B43: Schneider elementautomat | C43: 25 | D43: 9.9 | E43: 0.5 | F43: 6mm2 Cu | H43: 6 | I43: =MID(F43,6,3) -> Cu | J43: 43 | K43: =IF(AND($A$20=$A43,$B$20=$B43,$C$20=$C43,$D$20=$D43,$E$20=$E43,$F$20=$F43),TRUE,"") -> #N/A | L43: =IF(K43=TRUE,J43,"") -> #N/A | M43: =IF(AND($A$21=$A43,$B$21=$B43,$C$21=$C43,$D$21=$D43,$E$21=$E43,$J$7<=J43),TRUE,"") | N43: =IF(M43=TRUE,J43,"") | O43: =IF(M43=TRUE,F43,"") | P43: =IF(AND($C$24=50,'Beregning AC vern'!U5="IT-230V"),FALSE,IF(AND($A$24=$A43,$B$24=$B43,$C$24=$C43,$D$24=$D43,$E$24=$E43),TRUE,"")) | Q43: =IF(P43=TRUE,J43,IF(P43=FALSE,FALSE)) -> FALSE | R43: =IF(P43=TRUE,F43,IF(P43=FALSE,"Data mangler")) -> FALSE
A44: IT-230V | B44: Schneider elementautomat | C44: 25 | D44: 9.9 | E44: 0.5 | F44: 10mm2 Cu | H44: 10 | I44: =MID(F44,6,3) -> Cu | J44: 73 | K44: =IF(AND($A$20=$A44,$B$20=$B44,$C$20=$C44,$D$20=$D44,$E$20=$E44,$F$20=$F44),TRUE,"") -> #N/A | L44: =IF(K44=TRUE,J44,"") -> #N/A | M44: =IF(AND($A$21=$A44,$B$21=$B44,$C$21=$C44,$D$21=$D44,$E$21=$E44,$J$7<=J44),TRUE,"") | N44: =IF(M44=TRUE,J44,"") | O44: =IF(M44=TRUE,F44,"") | P44: =IF(AND($C$24=50,'Beregning AC vern'!U6="IT-230V"),FALSE,IF(AND($A$24=$A44,$B$24=$B44,$C$24=$C44,$D$24=$D44,$E$24=$E44),TRUE,"")) | Q44: =IF(P44=TRUE,J44,IF(P44=FALSE,FALSE)) -> FALSE | R44: =IF(P44=TRUE,F44,IF(P44=FALSE,"Data mangler")) -> FALSE
A45: IT-230V | B45: Schneider elementautomat | C45: 25 | D45: 9.9 | E45: 0.5 | F45: 25mm2 Al | H45: 25 | I45: =MID(F45,6,3) -> Al | J45: 110 | K45: =IF(AND($A$20=$A45,$B$20=$B45,$C$20=$C45,$D$20=$D45,$E$20=$E45,$F$20=$F45),TRUE,"") -> #N/A | L45: =IF(K45=TRUE,J45,"") -> #N/A | M45: =IF(AND($A$21=$A45,$B$21=$B45,$C$21=$C45,$D$21=$D45,$E$21=$E45,$J$7<=J45),TRUE,"") | N45: =IF(M45=TRUE,J45,"") | O45: =IF(M45=TRUE,F45,"") | P45: =IF(AND($C$24=50,'Beregning AC vern'!U7="IT-230V"),FALSE,IF(AND($A$24=$A45,$B$24=$B45,$C$24=$C45,$D$24=$D45,$E$24=$E45),TRUE,"")) | Q45: =IF(P45=TRUE,J45,IF(P45=FALSE,FALSE)) -> FALSE | R45: =IF(P45=TRUE,F45,IF(P45=FALSE,"Data mangler")) -> FALSE
A46: IT-230V | B46: Schneider elementautomat | C46: 25 | D46: 9.9 | E46: 0.5 | F46: 50mm2 Al | H46: 50 | I46: =MID(F46,6,3) -> Al | J46: 204 | K46: =IF(AND($A$20=$A46,$B$20=$B46,$C$20=$C46,$D$20=$D46,$E$20=$E46,$F$20=$F46),TRUE,"") -> #N/A | L46: =IF(K46=TRUE,J46,"") -> #N/A | M46: =IF(AND($A$21=$A46,$B$21=$B46,$C$21=$C46,$D$21=$D46,$E$21=$E46,$J$7<=J46),TRUE,"") | N46: =IF(M46=TRUE,J46,"") | O46: =IF(M46=TRUE,F46,"") | P46: =IF(AND($C$24=50,'Beregning AC vern'!U8="IT-230V"),FALSE,IF(AND($A$24=$A46,$B$24=$B46,$C$24=$C46,$D$24=$D46,$E$24=$E46),TRUE,"")) | Q46: =IF(P46=TRUE,J46,IF(P46=FALSE,FALSE)) -> FALSE | R46: =IF(P46=TRUE,F46,IF(P46=FALSE,"Data mangler")) -> FALSE
A47: IT-230V | B47: Schneider elementautomat | C47: 32 | D47: 9.9 | E47: 0.5 | F47: 10mm2 Cu | H47: 10 | I47: =MID(F47,6,3) -> Cu | J47: 44 | K47: =IF(AND($A$20=$A47,$B$20=$B47,$C$20=$C47,$D$20=$D47,$E$20=$E47,$F$20=$F47),TRUE,"") -> #N/A | L47: =IF(K47=TRUE,J47,"") -> #N/A | M47: =IF(AND($A$21=$A47,$B$21=$B47,$C$21=$C47,$D$21=$D47,$E$21=$E47,$J$7<=J47),TRUE,"") | N47: =IF(M47=TRUE,J47,"") | O47: =IF(M47=TRUE,F47,"") | P47: =IF(AND($C$24=50,'Beregning AC vern'!U9="IT-230V"),FALSE,IF(AND($A$24=$A47,$B$24=$B47,$C$24=$C47,$D$24=$D47,$E$24=$E47),TRUE,"")) | Q47: =IF(P47=TRUE,J47,IF(P47=FALSE,FALSE)) -> FALSE | R47: =IF(P47=TRUE,F47,IF(P47=FALSE,"Data mangler")) -> FALSE
A48: IT-230V | B48: Schneider elementautomat | C48: 32 | D48: 9.9 | E48: 0.5 | F48: 25mm2 Al | H48: 25 | I48: =MID(F48,6,3) -> Al | J48: 66 | K48: =IF(AND($A$20=$A48,$B$20=$B48,$C$20=$C48,$D$20=$D48,$E$20=$E48,$F$20=$F48),TRUE,"") -> #N/A | L48: =IF(K48=TRUE,J48,"") -> #N/A | M48: =IF(AND($A$21=$A48,$B$21=$B48,$C$21=$C48,$D$21=$D48,$E$21=$E48,$J$7<=J48),TRUE,"") | N48: =IF(M48=TRUE,J48,"") | O48: =IF(M48=TRUE,F48,"") | P48: =IF(AND($C$24=50,'Beregning AC vern'!U10="IT-230V"),FALSE,IF(AND($A$24=$A48,$B$24=$B48,$C$24=$C48,$D$24=$D48,$E$24=$E48),TRUE,"")) | Q48: =IF(P48=TRUE,J48,IF(P48=FALSE,FALSE)) -> FALSE | R48: =IF(P48=TRUE,F48,IF(P48=FALSE,"Data mangler")) -> FALSE
A49: IT-230V | B49: Schneider elementautomat | C49: 32 | D49: 9.9 | E49: 0.5 | F49: 50mm2 Al | H49: 50 | I49: =MID(F49,6,3) -> Al | J49: 123 | K49: =IF(AND($A$20=$A49,$B$20=$B49,$C$20=$C49,$D$20=$D49,$E$20=$E49,$F$20=$F49),TRUE,"") -> #N/A | L49: =IF(K49=TRUE,J49,"") -> #N/A | M49: =IF(AND($A$21=$A49,$B$21=$B49,$C$21=$C49,$D$21=$D49,$E$21=$E49,$J$7<=J49),TRUE,"") | N49: =IF(M49=TRUE,J49,"") | O49: =IF(M49=TRUE,F49,"") | P49: =IF(AND($C$24=50,'Beregning AC vern'!U11="IT-230V"),FALSE,IF(AND($A$24=$A49,$B$24=$B49,$C$24=$C49,$D$24=$D49,$E$24=$E49),TRUE,"")) | Q49: =IF(P49=TRUE,J49,IF(P49=FALSE,FALSE)) -> FALSE | R49: =IF(P49=TRUE,F49,IF(P49=FALSE,"Data mangler")) -> FALSE
A50: IT-230V | B50: Schneider elementautomat | C50: 40 | D50: 9.9 | E50: 0.5 | F50: 16mm2 Cu | H50: 16 | I50: =MID(F50,6,3) -> Cu | J50: 45 | K50: =IF(AND($A$20=$A50,$B$20=$B50,$C$20=$C50,$D$20=$D50,$E$20=$E50,$F$20=$F50),TRUE,"") -> #N/A | L50: =IF(K50=TRUE,J50,"") -> #N/A | M50: =IF(AND($A$21=$A50,$B$21=$B50,$C$21=$C50,$D$21=$D50,$E$21=$E50,$J$7<=J50),TRUE,"") | N50: =IF(M50=TRUE,J50,"") | O50: =IF(M50=TRUE,F50,"") | P50: =IF(AND($C$24=50,'Beregning AC vern'!U12="IT-230V"),FALSE,IF(AND($A$24=$A50,$B$24=$B50,$C$24=$C50,$D$24=$D50,$E$24=$E50),TRUE,"")) | Q50: =IF(P50=TRUE,J50,IF(P50=FALSE,FALSE)) -> FALSE | R50: =IF(P50=TRUE,F50,IF(P50=FALSE,"Data mangler")) -> FALSE
A51: IT-230V | B51: Schneider elementautomat | C51: 40 | D51: 9.9 | E51: 0.5 | F51: 25mm2 Al | H51: 25 | I51: =MID(F51,6,3) -> Al | J51: 43 | K51: =IF(AND($A$20=$A51,$B$20=$B51,$C$20=$C51,$D$20=$D51,$E$20=$E51,$F$20=$F51),TRUE,"") -> #N/A | L51: =IF(K51=TRUE,J51,"") -> #N/A | M51: =IF(AND($A$21=$A51,$B$21=$B51,$C$21=$C51,$D$21=$D51,$E$21=$E51,$J$7<=J51),TRUE,"") | N51: =IF(M51=TRUE,J51,"") | O51: =IF(M51=TRUE,F51,"") | P51: =IF(AND($C$24=50,'Beregning AC vern'!U13="IT-230V"),FALSE,IF(AND($A$24=$A51,$B$24=$B51,$C$24=$C51,$D$24=$D51,$E$24=$E51),TRUE,"")) | Q51: =IF(P51=TRUE,J51,IF(P51=FALSE,FALSE)) -> FALSE | R51: =IF(P51=TRUE,F51,IF(P51=FALSE,"Data mangler")) -> FALSE
A52: IT-230V | B52: Schneider elementautomat | C52: 40 | D52: 9.9 | E52: 0.5 | F52: 50mm2 Al | H52: 50 | I52: =MID(F52,6,3) -> Al | J52: 80 | K52: =IF(AND($A$20=$A52,$B$20=$B52,$C$20=$C52,$D$20=$D52,$E$20=$E52,$F$20=$F52),TRUE,"") -> #N/A | L52: =IF(K52=TRUE,J52,"") -> #N/A | M52: =IF(AND($A$21=$A52,$B$21=$B52,$C$21=$C52,$D$21=$D52,$E$21=$E52,$J$7<=J52),TRUE,"") | N52: =IF(M52=TRUE,J52,"") | O52: =IF(M52=TRUE,F52,"") | P52: =IF(AND($C$24=50,'Beregning AC vern'!U14="IT-230V"),FALSE,IF(AND($A$24=$A52,$B$24=$B52,$C$24=$C52,$D$24=$D52,$E$24=$E52),TRUE,"")) | Q52: =IF(P52=TRUE,J52,IF(P52=FALSE,FALSE)) -> FALSE | R52: =IF(P52=TRUE,F52,IF(P52=FALSE,"Data mangler")) -> FALSE
... A101: IT-230V | B101: Schneider elementautomat | C101: 80 | D101: 9.9 | E101: 8.5 | F101: 50mm2 Al | H101: 50 | I101: =MID(F101,6,3) -> Al | J101: 171 | K101: =IF(AND($A$20=$A101,$B$20=$B101,$C$20=$C101,$D$20=$D101,$E$20=$E101,$F$20=$F101),TRUE,"") -> #N/A | L101: =IF(K101=TRUE,J101,"") -> #N/A | M101: =IF(AND($A$21=$A101,$B$21=$B101,$C$21=$C101,$D$21=$D101,$E$21=$E101,$J$7<=J101),TRUE,"") | N101: =IF(M101=TRUE,J101,"") | O101: =IF(M101=TRUE,F101,"") | P101: =IF(AND($C$24=50,'Beregning AC vern'!U63="IT-230V"),FALSE,IF(AND($A$24=$A101,$B$24=$B101,$C$24=$C101,$D$24=$D101,$E$24=$E101),TRUE,"")) | Q101: =IF(P101=TRUE,J101,IF(P101=FALSE,FALSE)) -> FALSE | R101: =IF(P101=TRUE,F101,IF(P101=FALSE,"Data mangler")) -> FALSE
A102: Nettsystem | B102: Vernleverandør | C102: Vern (A) | D102: Ikpmaks (kA) | E102: Ikpmin (kA) | F102: Tversnitt | H102: Nytt tverrsnitt | I102: Ledertype | J102: Kabellengde (m) | K102: =IF(AND($A$20=$A102,$B$20=$B102,$C$20=$C102,$D$20=$D102,$E$20=$E102,$F$20=$F102),TRUE,"") -> #N/A | L102: =IF(K102=TRUE,J102,"") -> #N/A | M102: =IF(AND($A$21=$A102,$B$21=$B102,$C$21=$C102,$D$21=$D102,$E$21=$E102,$J$7<=J102),TRUE,"") | N102: =IF(M102=TRUE,J102,"") | O102: =IF(M102=TRUE,F102,"") | P102: =IF(AND($C$24=50,'Beregning AC vern'!U64="IT-230V"),FALSE,IF(AND($A$24=$A102,$B$24=$B102,$C$24=$C102,$D$24=$D102,$E$24=$E102),TRUE,"")) | Q102: =IF(P102=TRUE,J102,IF(P102=FALSE,FALSE)) -> FALSE | R102: =IF(P102=TRUE,F102,IF(P102=FALSE,"Data mangler")) -> FALSE
A103: TN-400V | B103: Schneider elementautomat | C103: 25 | D103: 9.9 | E103: 0.25 | F103: 6mm2 Cu | H103: 6 | I103: =MID(F103,6,3) -> Cu | J103: 52 | K103: =IF(AND($A$20=$A103,$B$20=$B103,$C$20=$C103,$D$20=$D103,$E$20=$E103,$F$20=$F103),TRUE,"") -> #N/A | L103: =IF(K103=TRUE,J103,"") -> #N/A | M103: =IF(AND($A$21=$A103,$B$21=$B103,$C$21=$C103,$D$21=$D103,$E$21=$E103,$J$7<=J103),TRUE,"") | N103: =IF(M103=TRUE,J103,"") | O103: =IF(M103=TRUE,F103,"") | P103: =IF(AND($C$24=50,'Beregning AC vern'!U65="IT-230V"),FALSE,IF(AND($A$24=$A103,$B$24=$B103,$C$24=$C103,$D$24=$D103,$E$24=$E103),TRUE,"")) | Q103: =IF(P103=TRUE,J103,IF(P103=FALSE,FALSE)) -> FALSE | R103: =IF(P103=TRUE,F103,IF(P103=FALSE,"Data mangler")) -> FALSE | V103: Oversikt TN-anlegg 400V | X103: Kortslutningstrømmer: | AA103: Ikpmaks | AB103: Ikpmin
A104: TN-400V | B104: Schneider elementautomat | C104: 25 | D104: 9.9 | E104: 0.25 | F104: 10mm2 Cu | H104: 10 | I104: =MID(F104,6,3) -> Cu | J104: 86 | K104: =IF(AND($A$20=$A104,$B$20=$B104,$C$20=$C104,$D$20=$D104,$E$20=$E104,$F$20=$F104),TRUE,"") -> #N/A | L104: =IF(K104=TRUE,J104,"") -> #N/A | M104: =IF(AND($A$21=$A104,$B$21=$B104,$C$21=$C104,$D$21=$D104,$E$21=$E104,$J$7<=J104),TRUE,"") | N104: =IF(M104=TRUE,J104,"") | O104: =IF(M104=TRUE,F104,"") | P104: =IF(AND($C$24=50,'Beregning AC vern'!U66="IT-230V"),FALSE,IF(AND($A$24=$A104,$B$24=$B104,$C$24=$C104,$D$24=$D104,$E$24=$E104),TRUE,"")) | Q104: =IF(P104=TRUE,J104,IF(P104=FALSE,FALSE)) -> FALSE | R104: =IF(P104=TRUE,F104,IF(P104=FALSE,"Data mangler")) -> FALSE | V104: Vern for stigere til Ice U.F | AA104: 9,9kA | AB104: 0,25-8,5kA
A105: TN-400V | B105: Schneider elementautomat | C105: 25 | D105: 9.9 | E105: 0.25 | F105: 25mm2 Al | H105: 25 | I105: =MID(F105,6,3) -> Al | J105: 132 | K105: =IF(AND($A$20=$A105,$B$20=$B105,$C$20=$C105,$D$20=$D105,$E$20=$E105,$F$20=$F105),TRUE,"") -> #N/A | L105: =IF(K105=TRUE,J105,"") -> #N/A | M105: =IF(AND($A$21=$A105,$B$21=$B105,$C$21=$C105,$D$21=$D105,$E$21=$E105,$J$7<=J105),TRUE,"") | N105: =IF(M105=TRUE,J105,"") | O105: =IF(M105=TRUE,F105,"") | P105: =IF(AND($C$24=50,'Beregning AC vern'!U67="IT-230V"),FALSE,IF(AND($A$24=$A105,$B$24=$B105,$C$24=$C105,$D$24=$D105,$E$24=$E105),TRUE,"")) | Q105: =IF(P105=TRUE,J105,IF(P105=FALSE,FALSE)) -> FALSE | R105: =IF(P105=TRUE,F105,IF(P105=FALSE,"Data mangler")) -> FALSE | V105: Schneider elementautomat
...

Sheet Kabellengder AC
A1: Oversikt IT-anlegg 230V | C1: Kortslutningstrømmer: | F1: Ikpmaks | G1: Ikpmin | I1: Oversikt TN-anlegg 400V | K1: Kortslutningstrømmer: | N1: Ikpmaks | O1: Ikpmin | Q1: Oversikt IT-anlegg 230V | S1: Kortslutningstrømmer: | T1: Ikpmaks | W1: Ikpmin | Y1: Oversikt TN-anlegg 400V | AA1: Kortslutningstrømmer: | AB1: Ikpmaks | AE1: Ikpmin | AG1: Oversikt IT-anlegg 230V | AI1: Kortslutningstrømmer: | AL1: Ikpmaks | AM1: Ikpmin | AO1: Oversikt TN-anlegg 400V | AQ1: Kortslutningstrømmer: | AT1: Ikpmaks | AU1: Ikpmin
A2: vern i H.F for hovedkabler | F2: 9,9kA | G2: 0,25-8,5kA | I2: Vern for stigere til Ice U.F | N2: 9,9kA | O2: 0,25-8,5kA | Q2: vern i H.F for hovedkabler | T2: 9,9kA | W2: 0,25-8,5kA | Y2: Vern for stigere til Ice U.F | AB2: 9,9kA | AE2: 0,25-8,5kA | AG2: Vern for stigere til Ice U.F | AL2: 19,9kA | AM2: 15kA | AO2: Vern for stigere til Ice U.F | AT2: 19,9kA | AU2: 15kA
A3: Schneider elementautomat | I3: Schneider elementautomat | Q3: Eaton elementautomat | Y3: Eaton elementautomat | AG3: Schneider effektbryter | AO3: Schneider effektbryter
A4: Vern (A) | B4: Ikpmaks (kA) | C4: Ikpmin (kA) | D4: Tversnitt | E4: Nytt tverrsnitt | F4: Ledertype | G4: Kabellengde (m) | I4: Vern (A) | J4: Ikpmaks (kA) | K4: Ikpmin (kA) | L4: Tversnitt | M4: Nytt tverrsnitt | N4: Ledertype | O4: Kabellengde (m) | Q4: Vern (A) | R4: Ikpmaks (kA) | S4: Ikpmin (kA) | T4: Tversnitt | U4: Nytt tverrsnitt | V4: Ledertype | W4: Kabellengde (m) | Y4: Vern (A) | Z4: Ikpmaks (kA) | AA4: Ikpmin (kA) | AB4: Tversnitt | AC4: Nytt tverrsnitt | AD4: Ledertype | AE4: Kabellengde (m) | AG4: Vern (A) | AH4: Ikpmaks (kA) | AI4: Ikpmin (kA) | AJ4: Tversnitt | AK4: Nytt tverrsnitt | AL4: Ledertype | AM4: Kabellengde (m) | AO4: Vern (A) | AP4: Ikpmaks (kA) | AQ4: Ikpmin (kA) | AR4: Tversnitt | AS4: Nytt tverrsnitt | AT4: Ledertype | AU4: Kabellengde (m)
A5: 25 | B5: 9.9 | C5: 0.25 | D5: 6mm2 Cu | E5: 6 | F5: =MID(D5,6,3) -> Cu | G5: 15 | I5: 25 | J5: 9.9 | K5: 0.25 | L5: 6mm2 Cu | M5: 6 | N5: =MID(L5,6,3) -> Cu | O5: 52 | Q5: 25 | R5: 9.9 | S5: 0.25 | T5: 6mm2 Cu | U5: 6 | V5: =MID(T5,6,3) -> Cu | W5: 58 | Y5: 25 | Z5: 9.9 | AA5: 0.25 | AB5: 6mm2 Cu | AC5: 6 | AD5: =MID(AB5,6,3) -> Cu | AE5: 108 | AG5: 25 | AH5: 19.9 | AI5: 10 | AJ5: 6mm2 Cu | AK5: 6 | AL5: =MID(AJ5,6,3) -> Cu | AM5: 63 | AO5: 25 | AP5: 19.9 | AQ5: 10 | AR5: 6mm2 Cu | AS5: 6 | AT5: =MID(AR5,6,3) -> Cu | AU5: 109
A6: 25 | B6: 9.9 | C6: 0.25 | D6: 10mm2 Cu | E6: 10 | F6: =MID(D6,6,3) -> Cu | G6: 25 | I6: 25 | J6: 9.9 | K6: 0.25 | L6: 10mm2 Cu | M6: 10 | N6: =MID(L6,6,3) -> Cu | O6: 86 | Q6: 25 | R6: 9.9 | S6: 0.25 | T6: 10mm2 Cu | U6: 10 | V6: =MID(T6,6,3) -> Cu | W6: 98 | Y6: 25 | Z6: 9.9 | AA6: 0.25 | AB6: 10mm2 Cu | AC6: 10 | AD6: =MID(AB6,6,3) -> Cu | AE6: 170 | AG6: 25 | AH6: 19.9 | AI6: 10 | AJ6: 10mm2 Cu | AK6: 10 | AL6: =MID(AJ6,6,3) -> Cu | AM6: 105 | AO6: 25 | AP6: 19.9 | AQ6: 10 | AR6: 10mm2 Cu | AS6: 10 | AT6: =MID(AR6,6,3) -> Cu | AU6: 181
A7: 25 | B7: 9.9 | C7: 0.25 | D7: 25mm2 Al | E7: 25 | F7: =MID(D7,6,3) -> Al | G7: 38 | I7: 25 | J7: 9.9 | K7: 0.25 | L7: 25mm2 Al | M7: 25 | N7: =MID(L7,6,3) -> Al | O7: 132 | Q7: 25 | R7: 9.9 | S7: 0.25 | T7: 25mm2 Al | U7: 25 | V7: =MID(T7,6,3) -> Al | W7: 145 | Y7: 25 | Z7: 9.9 | AA7: 0.25 | AB7: 25mm2 Al | AC7: 25 | AD7: =MID(AB7,6,3) -> Al | AE7: 270 | AG7: 25 | AH7: 19.9 | AI7: 10 | AJ7: 25mm2 Al | AK7: 25 | AL7: =MID(AJ7,6,3) -> Al | AM7: 158 | AO7: 25 | AP7: 19.9 | AQ7: 10 | AR7: 25mm2 Al | AS7: 25 | AT7: =MID(AR7,6,3) -> Al | AU7: 271
A8: 25 | B8: 9.9 | C8: 0.25 | D8: 50mm2 Al | E8: 50 | F8: =MID(D8,6,3) -> Al | G8: 69 | I8: 25 | J8: 9.9 | K8: 0.25 | L8: 50mm2 Al | M8: 50 | N8: =MID(L8,6,3) -> Al | O8: 241 | Q8: 25 | R8: 9.9 | S8: 0.25 | T8: 50mm2 Al | U8: 50 | V8: =MID(T8,6,3) -> Al | W8: 260 | Y8: 25 | Z8: 9.9 | AA8: 0.25 | AB8: 50mm2 Al | AC8: 50 | AD8: =MID(AB8,6,3) -> Al | AE8: 475 | AG8: 25 | AH8: 19.9 | AI8: 10 | AJ8: 50mm2 Al | AK8: 50 | AL8: =MID(AJ8,6,3) -> Al | AM8: 289 | AO8: 25 | AP8: 19.9 | AQ8: 10 | AR8: 50mm2 Al | AS8: 50 | AT8: =MID(AR8,6,3) -> Al | AU8: 490
A9: 25 | B9: 9.9 | C9: 0.5 | D9: 6mm2 Cu | E9: 6 | F9: =MID(D9,6,3) -> Cu | G9: 43 | I9: 25 | J9: 9.9 | K9: 0.5 | L9: 6mm2 Cu | M9: 6 | N9: =MID(L9,6,3) -> Cu | O9: 75 | Q9: 32 | R9: 9.9 | S9: 0.25 | T9: 10mm2 Cu | U9: 10 | V9: =MID(T9,6,3) -> Cu | W9: 55 | Y9: 32 | Z9: 9.9 | AA9: 0.25 | AB9: 10mm2 Cu | AC9: 10 | AD9: =MID(AB9,6,3) -> Cu | AE9: 142 | AG9: 32 | AH9: 19.9 | AI9: 10 | AJ9: 10mm2 Cu | AK9: 10 | AL9: =MID(AJ9,6,3) -> Cu | AM9: 82 | AO9: 32 | AP9: 19.9 | AQ9: 10 | AR9: 10mm2 Cu | AS9: 10 | AT9: =MID(AR9,6,3) -> Cu | AU9: 140
A10: 25 | B10: 9.9 | C10: 0.5 | D10: 10mm2 Cu | E10: 10 | F10: =MID(D10,6,3) -> Cu | G10: 73 | I10: 25 | J10: 9.9 | K10: 0.5 | L10: 10mm2 Cu | M10: 10 | N10: =MID(L10,6,3) -> Cu | O10: 127 | Q10: 32 | R10: 9.9 | S10: 0.25 | T10: 25mm2 Al | U10: 25 | V10: =MID(T10,6,3) -> Al | W10: 82 | Y10: 32 | Z10: 9.9 | AA10: 0.25 | AB10: 25mm2 Al | AC10: 25 | AD10: =MID(AB10,6,3) -> Al | AE10: 210 | AG10: 32 | AH10: 19.9 | AI10: 10 | AJ10: 25mm2 Al | AK10: 25 | AL10: =MID(AJ10,6,3) -> Al | AM10: 124 | AO10: 32 | AP10: 19.9 | AQ10: 10 | AR10: 25mm2 Al | AS10: 25 | AT10: =MID(AR10,6,3) -> Al | AU10: 214
A11: 25 | B11: 9.9 | C11: 0.5 | D11: 25mm2 Al | E11: 25 | F11: =MID(D11,6,3) -> Al | G11: 110 | I11: 25 | J11: 9.9 | K11: 0.5 | L11: 25mm2 Al | M11: 25 | N11: =MID(L11,6,3) -> Al | O11: 199 | Q11: 32 | R11: 9.9 | S11: 0.25 | T11: 50mm2 Al | U11: 50 | V11: =MID(T11,6,3) -> Al | W11: 150 | Y11: 32 | Z11: 9.9 | AA11: 0.25 | AB11: 50mm2 Al | AC11: 50 | AD11: =MID(AB11,6,3) -> Al | AE11: 380 | AG11: 32 | AH11: 19.9 | AI11: 10 | AJ11: 50mm2 Al | AK11: 50 | AL11: =MID(AJ11,6,3) -> Al | AM11: 226 | AO11: 32 | AP11: 19.9 | AQ11: 10 | AR11: 50mm2 Al | AS11: 50 | AT11: =MID(AR11,6,3) -> Al | AU11: 390
A12: 25 | B12: 9.9 | C12: 0.5 | D12: 50mm2 Al | E12: 50 | F12: =MID(D12,6,3) -> Al | G12: 204 | I12: 25 | J12: 9.9 | K12: 0.5 | L12: 50mm2 Al | M12: 50 | N12: =MID(L12,6,3) -> Al | O12: 368 | Q12: 40 | R12: 9.9 | S12: 0.25 | T12: 16mm2 Cu | U12: 16 | V12: =MID(T12,6,3) -> Cu | W12: 37 | Y12: 40 | Z12: 9.9 | AA12: 0.25 | AB12: 16mm2 Cu | AC12: 16 | AD12: =MID(AB12,6,3) -> Cu | AE12: 135 | AG12: 40 | AH12: 19.9 | AI12: 10 | AJ12: 25mm2 Cu | AK12: 25 | AL12: =MID(AJ12,6,3) -> Cu | AM12: 160 | AO12: 40 | AP12: 19.9 | AQ12: 10 | AR12: 25mm2 Cu | AS12: 25 | AT12: =MID(AR12,6,3) -> Cu | AU12: 179
A13: 32 | B13: 9.9 | C13: 0.5 | D13: 10mm2 Cu | E13: 10 | F13: =MID(D13,6,3) -> Cu | G13: 44 | I13: 32 | J13: 9.9 | K13: 0.5 | L13: 10mm2 Cu | M13: 10 | N13: =MID(L13,6,3) -> Cu | O13: 73 | Q13: 40 | R13: 9.9 | S13: 0.25 | T13: 25mm2 Al | U13: 25 | V13: =MID(T13,6,3) -> Al | W13: 37 | Y13: 40 | Z13: 9.9 | AA13: 0.25 | AB13: 25mm2 Al | AC13: 25 | AD13: =MID(AB13,6,3) -> Al | AE13: 125 | AG13: 40 | AH13: 19.9 | AI13: 10 | AJ13: 25mm2 Al | AK13: 25 | AL13: =MID(AJ13,6,3) -> Al | AM13: 99 | AO13: 40 | AP13: 19.9 | AQ13: 10 | AR13: 25mm2 Al | AS13: 25 | AT13: =MID(AR13,6,3) -> Al | AU13: 170
A14: 32 | B14: 9.9 | C14: 0.5 | D14: 25mm2 Al | E14: 25 | F14: =MID(D14,6,3) -> Al | G14: 66 | I14: 32 | J14: 9.9 | K14: 0.5 | L14: 25mm2 Al | M14: 25 | N14: =MID(L14,6,3) -> Al | O14: 111 | Q14: 40 | R14: 9.9 | S14: 0.25 | T14: 50mm2 Al | U14: 50 | V14: =MID(T14,6,3) -> Al | W14: 68 | Y14: 40 | Z14: 9.9 | AA14: 0.25 | AB14: 50mm2 Al | AC14: 50 | AD14: =MID(AB14,6,3) -> Al | AE14: 240 | AG14: 40 | AH14: 19.9 | AI14: 10 | AJ14: 50mm2 Al | AK14: 50 | AL14: =MID(AJ14,6,3) -> Al | AM14: 180 | AO14: 40 | AP14: 19.9 | AQ14: 10 | AR14: 50mm2 Al | AS14: 50 | AT14: =MID(AR14,6,3) -> Al | AU14: 310
A15: 32 | B15: 9.9 | C15: 0.5 | D15: 50mm2 Al | E15: 50 | F15: =MID(D15,6,3) -> Al | G15: 123 | I15: 32 | J15: 9.9 | K15: 0.5 | L15: 50mm2 Al | M15: 50 | N15: =MID(L15,6,3) -> Al | O15: 205 | Q15: 25 | R15: 9.9 | S15: 0.5 | T15: 6mm2 Cu | U15: 6 | V15: =MID(T15,6,3) -> Cu | W15: 62 | Y15: 25 | Z15: 9.9 | AA15: 0.5 | AB15: 6mm2 Cu | AC15: 6 | AD15: =MID(AB15,6,3) -> Cu | AE15: 108 | AG15: 63 | AH15: 19.9 | AI15: 10 | AJ15: 50mm2 Al | AK15: 50 | AL15: =MID(AJ15,6,3) -> Al | AM15: 114 | AO15: 63 | AP15: 19.9 | AQ15: 10 | AR15: 50mm2 Al | AS15: 50 | AT15: =MID(AR15,6,3) -> Al | AU15: 195
A16: 40 | B16: 9.9 | C16: 0.5 | D16: 16mm2 Cu | E16: 16 | F16: =MID(D16,6,3) -> Cu | G16: 45 | I16: 40 | J16: 9.9 | K16: 0.5 | L16: 16mm2 Cu | M16: 16 | N16: =MID(L16,6,3) -> Cu | O16: 67 | Q16: 25 | R16: 9.9 | S16: 0.5 | T16: 10mm2 Cu | U16: 10 | V16: =MID(T16,6,3) -> Cu | W16: 104 | Y16: 25 | Z16: 9.9 | AA16: 0.5 | AB16: 10mm2 Cu | AC16: 10 | AD16: =MID(AB16,6,3) -> Cu | AE16: 180 | AG16: 80 | AH16: 19.9 | AI16: 10 | AJ16: 95mm2 Al | AK16: 95 | AL16: =MID(AJ16,6,3) -> Al | AM16: 169 | AO16: 80 | AP16: 19.9 | AQ16: 10 | AR16: 95mm2 Al | AS16: 95 | AT16: =MID(AR16,6,3) -> Al | AU16: 290
... A28: 40 | B28: 9.9 | C28: 1 | D28: 25mm2 Al | E28: 25 | F28: =MID(D28,6,3) -> Al | G28: 79 | I28: 40 | J28: 9.9 | K28: 1 | L28: 25mm2 Al | M28: 25 | N28: =MID(L28,6,3) -> Al | O28: 64 | Q28: 25 | R28: 9.9 | S28: 1 | T28: 25mm2 Al | U28: 25 | V28: =MID(T28,6,3) -> Al | W28: 155 | Y28: 25 | Z28: 9.9 | AA28: 1 | AB28: 6mm2 Cu | AC28: 6 | AD28: =MID(AB28,6,3) -> Cu | AE28: 108 | AG28: 80 | AH28: 19.9 | AI28: 15 | AJ28: 95mm2 Al | AK28: 95 | AL28: =MID(AJ28,6,3) -> Al | AM28: 169 | AO28: 80 | AP28: 19.9 | AQ28: 15 | AR28: 95mm2 Al | AS28: 95 | AT28: =MID(AR28,6,3) -> Al | AU28: 297
